<?xml version="1.0"?>
<robot xmlns:xacro="http://wiki.ros.org/xacro">

  <xacro:macro name="hatch_4040" params="
    name:=''
    prefix:=''
    parent:=''
    *origin">

    <joint name="${prefix}hatch_4040_frame_joint" type="fixed">
      <parent link="${prefix}${parent}"/>
      <child link="${prefix}hatch_4040_frame"/>
      <xacro:insert_block name="origin"/>
    </joint>

    <link name="${prefix}hatch_4040_frame">
      <!--TODO set proper inertia-->
      <inertial>
        <origin rpy="0 0 0" xyz="0.0 0.0 0.0"/>
        <mass value="0.0"/>
        <inertia ixx="0.0" ixy="0.0" ixz="0.0" iyy="0.0" iyz="0.0" izz="0.0"/>
      </inertial>
      <visual>
        <origin xyz="0.0 0.0 0.0" rpy="0 0 0"/>
        <geometry>
          <mesh filename="file://$(find hatch_4040)/meshes/visual/hatch_4040_frame.stl"/>
        </geometry>
        <material name="gray"/>
      </visual>
      <collision>
        <origin xyz="0.0 0.0 0.0" rpy="0 0 0"/>
        <geometry>
          <mesh filename="file://$(find hatch_4040)/meshes/visual/hatch_4040_frame.stl"/>
        </geometry>
        <material name="red"/>
      </collision>
    </link>

    <joint name="${prefix}hatch_4040_frame_face_joint" type="revolute">
      <axis xyz="0 0 1"/>
      <limit effort="10.0" lower="0.0" upper="3.14" velocity="0.5"/>
      <parent link="${prefix}hatch_4040_frame"/>
      <child link="${prefix}hatch_4040_face"/>
      <origin xyz="0.083 1.22 0.0982" rpy="0 0 0"/>
    </joint>

    <link name="${prefix}hatch_4040_face">
      <visual>
        <origin xyz="0.0 0.0 0.0" rpy="0 0 0"/>
        <geometry>
          <mesh filename="file://$(find hatch_4040)/meshes/visual/hatch_4040_face.stl"/>
        </geometry>
        <material name="gray"/>
      </visual>
      <collision>
        <origin xyz="0.0 0.0 0.0" rpy="0 0 0"/>
        <geometry>
          <mesh filename="file://$(find hatch_4040)/meshes/collision/hatch_4040_face.stl"/>
        </geometry>
        <material name="red"/>
      </collision>
    </link>

  </xacro:macro>
</robot>
