<?xml version="1.0"?>
<robot xmlns:xacro="http://wiki.ros.org/xacro">

  <xacro:macro name="bench_seat" params="
    prefix:=''
    parent:=''
    *origin">

    <joint name="${prefix}bench_base_joint" type="fixed">
      <parent link="${parent}"/>
      <child link="${prefix}bench_back"/>
      <xacro:insert_block name="origin"/>
    </joint>

    <link name="${prefix}bench_back">
      <!--TODO set proper inertia-->
      <inertial>
        <origin xyz="0.064 0.448 0.02" rpy="0 0 0"/>
        <mass value="12.32218"/>
        <inertia ixx="0.8241741" ixy="0.0" ixz="0.0" iyy="0.01820499" iyz="0.0" izz="0.8390932"/>
      </inertial>
      <visual>
        <origin xyz="${0.127/2} ${0.895/2} ${0.04/2}" rpy="0 0 0"/>
        <geometry>
          <box size="0.127 0.895 0.04"/>
        </geometry>
        <material name="gray"/>
      </visual>
      <collision>
        <origin xyz="${0.127/2} ${0.895/2} ${0.05/2}" rpy="0 0 0"/>
        <geometry>
          <box size="0.127 0.895 0.05"/>
        </geometry>
        <material name="red"/>
      </collision>
    </link>

    <joint name="${prefix}bench_left_joint" type="fixed">
      <parent link="${prefix}bench_back"/>
      <child link="${prefix}bench_left"/>
      <origin xyz="0.0 0.0 0.0" rpy="0 0 0"/>
    </joint>

    <link name="${prefix}bench_left">
      <inertial>
        <origin xyz="0.354 0.02 0.02" rpy="0 0 0"/>
        <mass value="3.070111"/>
        <inertia ixx="0.0008186962" ixy="0.0" ixz="0.0" iyy="0.128654" iyz="0.0" izz="0.128654"/>
      </inertial>
      <visual>
        <origin xyz="${0.708/2} ${0.04/2} ${0.04/2}" rpy="0 0 0"/>
        <geometry>
          <box size="0.708 0.04 0.04"/>
        </geometry>
        <material name="gray"/>
      </visual>
      <collision>
        <origin xyz="${0.708/2} ${0.05/2} ${0.05/2}" rpy="0 0 0"/>
        <geometry>
          <box size="0.708 0.05 0.05"/>
        </geometry>
        <material name="red"/>
      </collision>
    </link>

    <joint name="${prefix}bench_right_joint" type="fixed">
      <parent link="${prefix}bench_back"/>
      <child link="${prefix}bench_right"/>
      <origin xyz="0.0 0.84535 0.0" rpy="0 0 0"/>
    </joint>

    <link name="${prefix}bench_right">
      <inertial>
        <origin xyz="0.354 0.02 0.02" rpy="0 0 0"/>
        <mass value="3.070111"/>
        <inertia ixx="0.0008186962" ixy="0.0" ixz="0.0" iyy="0.128654" iyz="0.0" izz="0.128654"/>
      </inertial>
      <visual>
        <origin xyz="${0.708/2} ${0.05/2} ${0.04/2}" rpy="0 0 0"/>
        <geometry>
          <box size="0.708 0.04 0.04"/>
        </geometry>
        <material name="gray"/>
      </visual>
      <collision>
        <origin xyz="${0.708/2} ${0.05/2} ${0.05/2}" rpy="0 0 0"/>
        <geometry>
          <box size="0.708 0.05 0.05"/>
        </geometry>
        <material name="red"/>
      </collision>
    </link>

    <joint name="${prefix}bench_front_joint" type="fixed">
      <parent link="${prefix}bench_back"/>
      <child link="${prefix}bench_front"/>
      <origin xyz="0.6612 0.0 0.0" rpy="0 0 0"/>
    </joint>

    <link name="${prefix}bench_front">
       <inertial>
        <origin xyz="0.02 0.448 0.02" rpy="0 0 0"/>
        <mass value="3.881002"/>
        <inertia ixx="0.2595824" ixy="0.0" ixz="0.0" iyy="0.001034934" iyz="0.0" izz="0.2595824"/>
      </inertial>
      <visual>
        <origin xyz="${0.05/2} ${0.895/2} ${0.04/2}" rpy="0 0 0"/>
        <geometry>
          <box size="0.04 0.895 0.04"/>
        </geometry>
        <material name="gray"/>
      </visual>
      <collision>
        <origin xyz="${0.05/2} ${0.895/2} ${0.05/2}" rpy="0 0 0"/>
        <geometry>
          <box size="0.05 0.895 0.05"/>
        </geometry>
        <material name="red"/>
      </collision>
    </link>

    <joint name="${prefix}bench_lid_joint" type="revolute">
      <axis xyz="0 -1 0"/>
      <!-- upper is 95 degrees -->
      <limit effort="10.0" lower="0.0" upper="1.65806" velocity="0.5"/> 
      <parent link="${prefix}bench_back"/>
      <child link="${prefix}bench_lid"/>
      <origin xyz="0.127 0.0 0.0475" rpy="0 0 0"/>
    </joint>

    <link name="${prefix}bench_lid">
      <!--TODO set proper inertia-->
      <inertial>
        <origin xyz="0.2652256 0.46 0.03190335" rpy="0 0 0"/>
        <mass value="9.07185"/>
        <inertia ixx="0.643167" ixy="0.0" ixz="0.002867943" iyy="0.2210995" iyz="0.0" izz="0.8576681"/>
      </inertial>
      <visual>
        <origin xyz="0.0 0.0 0.0" rpy="0 0 0"/>
        <geometry>
          <mesh filename="package://trainer/meshes/visual/bench_lid.stl"/>
        </geometry>
        <material name="blue"/>
      </visual>
      <collision>
        <!--0.0075 is the radius of the hinge-->
        <origin xyz="${0.603/2 + 0.0075} ${0.920/2} ${0.065/2 - 0.0075}" rpy="0 0 0"/>
        <geometry>
          <box size="0.603 0.920 ${0.065/2}"/>
        </geometry>
        <material name="blue"/>
      </collision>
    </link>

    <joint name="${prefix}bench_left_cal_joint" type="fixed">
      <parent link="${prefix}bench_front"/>
      <child link="${prefix}bench_left_cal_frame"/>
      <origin xyz="0.045 0.0 0.0" rpy="0 0 0"/>
    </joint>

    <link name="${prefix}bench_left_cal_frame"/>

    <joint name="${prefix}bench_right_cal_joint" type="fixed">
      <parent link="${prefix}bench_right"/>
      <child link="${prefix}bench_right_cal_frame"/>
      <origin xyz="0.7062 0.05 0.0" rpy="0 0 0"/>
    </joint>

    <link name="${prefix}bench_right_cal_frame"/>

  </xacro:macro>
</robot>

